<?xml version="1.0" ?>
<!-- =================================================================================== -->
<!-- |    This document was autogenerated by xacro from urdf/assembly_main.xacro       | -->
<!-- |    EDITING THIS FILE BY HAND IS NOT RECOMMENDED                                 | -->
<!-- =================================================================================== -->
<robot name="assembly_main">
  <material name="silver_default">
    <color rgba="0.700 0.700 0.700 1.000"/>
  </material>
  <material name="steel_satin">
    <color rgba="0.6274509803921569 0.6274509803921569 0.6274509803921569 1.0"/>
  </material>
  <material name="aluminum_satin">
    <color rgba="0.9607843137254902 0.9607843137254902 0.9647058823529412 1.0"/>
  </material>
  <material name="abs_white">
    <color rgba="0.9647058823529412 0.9647058823529412 0.9529411764705882 1.0"/>
  </material>
  <transmission name="Revolute 1_tran">
    <type>transmission_interface/SimpleTransmission</type>
    <joint name="Revolute 1">
      <hardwareInterface>hardware_interface/EffortJointInterface</hardwareInterface>
    </joint>
    <actuator name="Revolute 1_actr">
      <hardwareInterface>hardware_interface/EffortJointInterface</hardwareInterface>
      <mechanicalReduction>1</mechanicalReduction>
    </actuator>
  </transmission>
  <transmission name="Revolute_2_tran">
    <type>transmission_interface/SimpleTransmission</type>
    <joint name="Revolute_2">
      <hardwareInterface>hardware_interface/EffortJointInterface</hardwareInterface>
    </joint>
    <actuator name="Revolute_2_actr">
      <hardwareInterface>hardware_interface/EffortJointInterface</hardwareInterface>
      <mechanicalReduction>1</mechanicalReduction>
    </actuator>
  </transmission>
  <transmission name="Revolute_3_tran">
    <type>transmission_interface/SimpleTransmission</type>
    <joint name="Revolute_3">
      <hardwareInterface>hardware_interface/EffortJointInterface</hardwareInterface>
    </joint>
    <actuator name="Revolute_3_actr">
      <hardwareInterface>hardware_interface/EffortJointInterface</hardwareInterface>
      <mechanicalReduction>1</mechanicalReduction>
    </actuator>
  </transmission>
  <transmission name="Revolute_4_tran">
    <type>transmission_interface/SimpleTransmission</type>
    <joint name="Revolute_4">
      <hardwareInterface>hardware_interface/EffortJointInterface</hardwareInterface>
    </joint>
    <actuator name="Revolute_4_actr">
      <hardwareInterface>hardware_interface/EffortJointInterface</hardwareInterface>
      <mechanicalReduction>1</mechanicalReduction>
    </actuator>
  </transmission>
  <transmission name="Revolute_5_tran">
    <type>transmission_interface/SimpleTransmission</type>
    <joint name="Revolute_5">
      <hardwareInterface>hardware_interface/EffortJointInterface</hardwareInterface>
    </joint>
    <actuator name="Revolute_5_actr">
      <hardwareInterface>hardware_interface/EffortJointInterface</hardwareInterface>
      <mechanicalReduction>1</mechanicalReduction>
    </actuator>
  </transmission>
  <transmission name="Revolute_6_tran">
    <type>transmission_interface/SimpleTransmission</type>
    <joint name="Revolute_6">
      <hardwareInterface>hardware_interface/EffortJointInterface</hardwareInterface>
    </joint>
    <actuator name="Revolute_6_actr">
      <hardwareInterface>hardware_interface/EffortJointInterface</hardwareInterface>
      <mechanicalReduction>1</mechanicalReduction>
    </actuator>
  </transmission>
  <link name="base_link">
    <inertial>
      <origin rpy="0 0 0" xyz="0.0016685480823734394 0.09587231603609693 0.01410222124869956"/>
      <mass value="10.0"/>
      <inertia ixx="0.013163" ixy="0.000254" ixz="-4.4e-05" iyy="0.013452" iyz="2.5e-05" izz="0.024089"/>
    </inertial>
    <visual>
      <origin rpy="0 0 0" xyz="0 0 0"/>
      <geometry>
        <mesh filename="../meshes/base_link.stl" scale="0.001 0.001 0.001"/>
      </geometry>
      <material name="aluminum_satin"/>
    </visual>
    <collision>
      <origin rpy="0 0 0" xyz="0 0 0"/>
      <geometry>
        <mesh filename="../meshes/base_link.stl" scale="0.001 0.001 0.001"/>
      </geometry>
    </collision>
  </link>
  <link name="arm_bracket_temp_v12_1">
    <inertial>
      <origin rpy="0 0 0" xyz="0.011893307409353286 0.004680842759964748 0.022739357849046002"/>
      <mass value="0.16496925038992882"/>
      <inertia ixx="9e-05" ixy="-1.7e-05" ixz="-8e-06" iyy="7e-05" iyz="5e-06" izz="5.2e-05"/>
    </inertial>
    <visual>
      <origin rpy="0 0 0" xyz="-0.035703 -0.064664 -0.0365"/>
      <geometry>
        <mesh filename="../meshes/arm_bracket_temp_v12_1.stl" scale="0.001 0.001 0.001"/>
      </geometry>
      <material name="steel_satin"/>
    </visual>
    <collision>
      <origin rpy="0 0 0" xyz="-0.035703 -0.064664 -0.0365"/>
      <geometry>
        <mesh filename="../meshes/arm_bracket_temp_v12_1.stl" scale="0.001 0.001 0.001"/>
      </geometry>
    </collision>
  </link>
  <link name="raspi4_bracket_v1_1">
    <inertial>
      <origin rpy="0 0 0" xyz="1.0358811586286266e-11 -0.004190801342254108 0.011212626337856427"/>
      <mass value="0.10292684148685698"/>
      <inertia ixx="2e-05" ixy="0.0" ixz="-0.0" iyy="4.1e-05" iyz="4e-06" izz="4.4e-05"/>
    </inertial>
    <visual>
      <origin rpy="0 0 0" xyz="-0.0 -0.176825 -0.0365"/>
      <geometry>
        <mesh filename="../meshes/raspi4_bracket_v1_1.stl" scale="0.001 0.001 0.001"/>
      </geometry>
      <material name="steel_satin"/>
    </visual>
    <collision>
      <origin rpy="0 0 0" xyz="-0.0 -0.176825 -0.0365"/>
      <geometry>
        <mesh filename="../meshes/raspi4_bracket_v1_1.stl" scale="0.001 0.001 0.001"/>
      </geometry>
    </collision>
  </link>
  <link name="raspi4_v2_1">
    <inertial>
      <origin rpy="0 0 0" xyz="3.881339694089547e-15 0.014999583655189608 0.03859010164223097"/>
      <mass value="0.7390104624417327"/>
      <inertia ixx="0.000465" ixy="0.0" ixz="1e-06" iyy="0.000631" iyz="0.0" izz="0.000215"/>
    </inertial>
    <visual>
      <origin rpy="0 0 0" xyz="-0.0 -0.163825 -0.0575"/>
      <geometry>
        <mesh filename="../meshes/raspi4_v2_1.stl" scale="0.001 0.001 0.001"/>
      </geometry>
      <material name="steel_satin"/>
    </visual>
    <collision>
      <origin rpy="0 0 0" xyz="-0.0 -0.163825 -0.0575"/>
      <geometry>
        <mesh filename="../meshes/raspi4_v2_1.stl" scale="0.001 0.001 0.001"/>
      </geometry>
    </collision>
  </link>
  <link name="lipo_bracket_v5_1">
    <inertial>
      <origin rpy="0 0 0" xyz="-0.02145046736939967 -0.02300777254127473 0.025572386759107592"/>
      <mass value="0.15095338739595293"/>
      <inertia ixx="0.000129" ixy="-1.2e-05" ixz="1e-06" iyy="0.000116" iyz="-0.0" izz="9.8e-05"/>
    </inertial>
    <visual>
      <origin rpy="0 0 0" xyz="0.040468 -0.155581 -0.0365"/>
      <geometry>
        <mesh filename="../meshes/lipo_bracket_v5_1.stl" scale="0.001 0.001 0.001"/>
      </geometry>
      <material name="steel_satin"/>
    </visual>
    <collision>
      <origin rpy="0 0 0" xyz="0.040468 -0.155581 -0.0365"/>
      <geometry>
        <mesh filename="../meshes/lipo_bracket_v5_1.stl" scale="0.001 0.001 0.001"/>
      </geometry>
    </collision>
  </link>
  <link name="DZ47B_63_circuit_breaker_holder_v3_1">
    <inertial>
      <origin rpy="0 0 0" xyz="0.02229875370121319 -0.03862280991922731 0.002938007686629586"/>
      <mass value="0.012274791356152887"/>
      <inertia ixx="1.5e-05" ixy="8e-06" ixz="-0.0" iyy="5e-06" iyz="0.0" izz="2e-05"/>
    </inertial>
    <visual>
      <origin rpy="0 0 0" xyz="0.088434 -0.095997 -0.0365"/>
      <geometry>
        <mesh filename="../meshes/DZ47B_63_circuit_breaker_holder_v3_1.stl" scale="0.001 0.001 0.001"/>
      </geometry>
      <material name="steel_satin"/>
    </visual>
    <collision>
      <origin rpy="0 0 0" xyz="0.088434 -0.095997 -0.0365"/>
      <geometry>
        <mesh filename="../meshes/DZ47B_63_circuit_breaker_holder_v3_1.stl" scale="0.001 0.001 0.001"/>
      </geometry>
    </collision>
  </link>
  <link name="arm_root_v4_1">
    <inertial>
      <origin rpy="0 0 0" xyz="0.022163724443126365 -0.012796901291084212 -0.009138901606431687"/>
      <mass value="0.06457976620923557"/>
      <inertia ixx="1.6e-05" ixy="5e-06" ixz="-1e-06" iyy="2.1e-05" iyz="0.0" izz="1.9e-05"/>
    </inertial>
    <visual>
      <origin rpy="0 0 0" xyz="-0.053261 -0.066075 -0.0765"/>
      <geometry>
        <mesh filename="../meshes/arm_root_v4_1.stl" scale="0.001 0.001 0.001"/>
      </geometry>
      <material name="abs_white"/>
    </visual>
    <collision>
      <origin rpy="0 0 0" xyz="-0.053261 -0.066075 -0.0765"/>
      <geometry>
        <mesh filename="../meshes/arm_root_v4_1.stl" scale="0.001 0.001 0.001"/>
      </geometry>
    </collision>
  </link>
  <link name="pitch_1_test_v3_1">
    <inertial>
      <origin rpy="0 0 0" xyz="0.0358303038564968 -0.019899545668259706 -0.00013072073296151177"/>
      <mass value="0.08186133563123103"/>
      <inertia ixx="3e-05" ixy="6e-06" ixz="-9e-06" iyy="4e-05" iyz="5e-06" izz="3.7e-05"/>
    </inertial>
    <visual>
      <origin rpy="0 0 0" xyz="-0.088941 -0.045475 -0.08955"/>
      <geometry>
        <mesh filename="../meshes/pitch_1_test_v3_1.stl" scale="0.001 0.001 0.001"/>
      </geometry>
      <material name="abs_white"/>
    </visual>
    <collision>
      <origin rpy="0 0 0" xyz="-0.088941 -0.045475 -0.08955"/>
      <geometry>
        <mesh filename="../meshes/pitch_1_test_v3_1.stl" scale="0.001 0.001 0.001"/>
      </geometry>
    </collision>
  </link>
  <link name="roll_1_test_v3_1">
    <inertial>
      <origin rpy="0 0 0" xyz="0.042100640863960814 0.00017256453450652937 0.015160914691842262"/>
      <mass value="0.07353297901744495"/>
      <inertia ixx="2.5e-05" ixy="2e-06" ixz="-0.0" iyy="2.7e-05" iyz="0.0" izz="2.1e-05"/>
    </inertial>
    <visual>
      <origin rpy="0 0 0" xyz="-0.132633 0.003249 -0.095"/>
      <geometry>
        <mesh filename="../meshes/roll_1_test_v3_1.stl" scale="0.001 0.001 0.001"/>
      </geometry>
      <material name="abs_white"/>
    </visual>
    <collision>
      <origin rpy="0 0 0" xyz="-0.132633 0.003249 -0.095"/>
      <geometry>
        <mesh filename="../meshes/roll_1_test_v3_1.stl" scale="0.001 0.001 0.001"/>
      </geometry>
    </collision>
  </link>
  <link name="pitch_2_test_v3_1">
    <inertial>
      <origin rpy="0 0 0" xyz="0.025973068908376362 -0.014769408547619371 -2.946918264967735e-10"/>
      <mass value="0.06668343069893205"/>
      <inertia ixx="1.5e-05" ixy="2e-06" ixz="-0.0" iyy="1.9e-05" iyz="0.0" izz="2.6e-05"/>
    </inertial>
    <visual>
      <origin rpy="0 0 0" xyz="-0.192076 0.013089 -0.095"/>
      <geometry>
        <mesh filename="../meshes/pitch_2_test_v3_1.stl" scale="0.001 0.001 0.001"/>
      </geometry>
      <material name="abs_white"/>
    </visual>
    <collision>
      <origin rpy="0 0 0" xyz="-0.192076 0.013089 -0.095"/>
      <geometry>
        <mesh filename="../meshes/pitch_2_test_v3_1.stl" scale="0.001 0.001 0.001"/>
      </geometry>
    </collision>
  </link>
  <link name="roll_2_test_v3_1">
    <inertial>
      <origin rpy="0 0 0" xyz="0.04210189544568463 0.000172164463575597 0.015187663571532464"/>
      <mass value="0.07365581710871624"/>
      <inertia ixx="2.5e-05" ixy="2e-06" ixz="-0.0" iyy="2.7e-05" iyz="0.0" izz="2.1e-05"/>
    </inertial>
    <visual>
      <origin rpy="0 0 0" xyz="-0.221587 0.054376 -0.095"/>
      <geometry>
        <mesh filename="../meshes/roll_2_test_v3_1.stl" scale="0.001 0.001 0.001"/>
      </geometry>
      <material name="abs_white"/>
    </visual>
    <collision>
      <origin rpy="0 0 0" xyz="-0.221587 0.054376 -0.095"/>
      <geometry>
        <mesh filename="../meshes/roll_2_test_v3_1.stl" scale="0.001 0.001 0.001"/>
      </geometry>
    </collision>
  </link>
  <link name="hand_unit_v3_1">
    <inertial>
      <origin rpy="0 0 0" xyz="0.027318565725242272 -0.01604965279786605 -0.011102966860764008"/>
      <mass value="0.0952280970557457"/>
      <inertia ixx="5.4e-05" ixy="1.1e-05" ixz="1.7e-05" iyy="6.8e-05" iyz="-8e-06" izz="5.4e-05"/>
    </inertial>
    <visual>
      <origin rpy="0 0 0" xyz="-0.281031 0.064216 -0.095"/>
      <geometry>
        <mesh filename="../meshes/hand_unit_v3_1.stl" scale="0.001 0.001 0.001"/>
      </geometry>
      <material name="abs_white"/>
    </visual>
    <collision>
      <origin rpy="0 0 0" xyz="-0.281031 0.064216 -0.095"/>
      <geometry>
        <mesh filename="../meshes/hand_unit_v3_1.stl" scale="0.001 0.001 0.001"/>
      </geometry>
    </collision>
  </link>
  <link name="hand_finger_v6_1">
    <inertial>
      <origin rpy="0 0 0" xyz="0.04229123613816288 0.0006403953404404278 0.02461729439488529"/>
      <mass value="0.024732672038933038"/>
      <inertia ixx="9e-06" ixy="4e-06" ixz="-3e-06" iyy="1.3e-05" iyz="2e-06" izz="1.8e-05"/>
    </inertial>
    <visual>
      <origin rpy="0 0 0" xyz="-0.292144 0.096267 -0.108"/>
      <geometry>
        <mesh filename="../meshes/hand_finger_v6_1.stl" scale="0.001 0.001 0.001"/>
      </geometry>
      <material name="abs_white"/>
    </visual>
    <collision>
      <origin rpy="0 0 0" xyz="-0.292144 0.096267 -0.108"/>
      <geometry>
        <mesh filename="../meshes/hand_finger_v6_1.stl" scale="0.001 0.001 0.001"/>
      </geometry>
    </collision>
  </link>
  <joint name="Rigid 4" type="fixed">
    <origin rpy="0 0 0" xyz="0.035703 0.064664 0.0365"/>
    <parent link="base_link"/>
    <child link="arm_bracket_temp_v12_1"/>
  </joint>
  <joint name="Rigid 7" type="fixed">
    <origin rpy="0 0 0" xyz="0.0 0.176825 0.0365"/>
    <parent link="base_link"/>
    <child link="raspi4_bracket_v1_1"/>
  </joint>
  <joint name="Rigid 8" type="fixed">
    <origin rpy="0 0 0" xyz="0.0 -0.013 0.021"/>
    <parent link="raspi4_bracket_v1_1"/>
    <child link="raspi4_v2_1"/>
  </joint>
  <joint name="Rigid 16" type="fixed">
    <origin rpy="0 0 0" xyz="-0.040468 0.155581 0.0365"/>
    <parent link="base_link"/>
    <child link="lipo_bracket_v5_1"/>
  </joint>
  <joint name="Rigid 17" type="fixed">
    <origin rpy="0 0 0" xyz="-0.088434 0.095997 0.0365"/>
    <parent link="base_link"/>
    <child link="DZ47B_63_circuit_breaker_holder_v3_1"/>
  </joint>
  <joint name="Rigid 26" type="fixed">
    <origin rpy="0 0 0" xyz="0.017558 0.001411 0.04"/>
    <parent link="arm_bracket_temp_v12_1"/>
    <child link="arm_root_v4_1"/>
  </joint>
  <joint name="Revolute 1" type="revolute">
    <origin rpy="0 0 0" xyz="0.03568 -0.0206 0.01305"/>
    <parent link="arm_root_v4_1"/>
    <child link="pitch_1_test_v3_1"/>
    <axis xyz="-0.0 0.0 -1.0"/>
    <limit effort="100" lower="-1.570796" upper="1.570796" velocity="100"/>
  </joint>
  <joint name="Revolute_2" type="revolute">
    <origin rpy="0 0 0" xyz="0.043692 -0.048724 0.00545"/>
    <parent link="pitch_1_test_v3_1"/>
    <child link="roll_1_test_v3_1"/>
    <axis xyz="0.5 0.866025 -0.0"/>
    <limit effort="100" lower="-1.396263" upper="1.919862" velocity="100"/>
  </joint>
  <joint name="Revolute_3" type="continuous">
    <origin rpy="0 0 0" xyz="0.059443 -0.00984 0.0"/>
    <parent link="roll_1_test_v3_1"/>
    <child link="pitch_2_test_v3_1"/>
    <axis xyz="0.866025 -0.5 0.0"/>
  </joint>
  <joint name="Revolute_4" type="revolute">
    <origin rpy="0 0 0" xyz="0.029511 -0.041287 0.0"/>
    <parent link="pitch_2_test_v3_1"/>
    <child link="roll_2_test_v3_1"/>
    <axis xyz="0.5 0.866025 0.0"/>
    <limit effort="100" lower="-1.48353" upper="1.919862" velocity="100"/>
  </joint>
  <joint name="Revolute_5" type="continuous">
    <origin rpy="0 0 0" xyz="0.059444 -0.00984 0.0"/>
    <parent link="roll_2_test_v3_1"/>
    <child link="hand_unit_v3_1"/>
    <axis xyz="-0.866025 0.5 -0.0"/>
  </joint>
  <joint name="Revolute_6" type="revolute">
    <origin rpy="0 0 0" xyz="0.011113 -0.032051 0.013"/>
    <parent link="hand_unit_v3_1"/>
    <child link="hand_finger_v6_1"/>
    <axis xyz="0.5 0.866025 0.0"/>
    <limit effort="100" lower="-1.047198" upper="0.872665" velocity="100"/>
  </joint>
</robot>
