<?xml version="1.0" ?>
<!-- =================================================================================== -->
<!-- |    This document was autogenerated by xacro from urdf/assembly_main.xacro       | -->
<!-- |    EDITING THIS FILE BY HAND IS NOT RECOMMENDED                                 | -->
<!-- =================================================================================== -->
<robot name="assembly_main">
  <material name="silver_default">
    <color rgba="0.700 0.700 0.700 1.000"/>
  </material>
  <material name="steel_satin">
    <color rgba="0.6274509803921569 0.6274509803921569 0.6274509803921569 1.0"/>
  </material>
  <material name="aluminum_satin">
    <color rgba="0.9607843137254902 0.9607843137254902 0.9647058823529412 1.0"/>
  </material>
  <material name="abs_white">
    <color rgba="0.9647058823529412 0.9647058823529412 0.9529411764705882 1.0"/>
  </material>
  <transmission name="Revolute_1_tran">
    <type>transmission_interface/SimpleTransmission</type>
    <joint name="Revolute_1">
      <hardwareInterface>hardware_interface/EffortJointInterface</hardwareInterface>
    </joint>
    <actuator name="Revolute_1_actr">
      <hardwareInterface>hardware_interface/EffortJointInterface</hardwareInterface>
      <mechanicalReduction>1</mechanicalReduction>
    </actuator>
  </transmission>
  <transmission name="Revolute_2_tran">
    <type>transmission_interface/SimpleTransmission</type>
    <joint name="Revolute_2">
      <hardwareInterface>hardware_interface/EffortJointInterface</hardwareInterface>
    </joint>
    <actuator name="Revolute_2_actr">
      <hardwareInterface>hardware_interface/EffortJointInterface</hardwareInterface>
      <mechanicalReduction>1</mechanicalReduction>
    </actuator>
  </transmission>
  <transmission name="Revolute_3_tran">
    <type>transmission_interface/SimpleTransmission</type>
    <joint name="Revolute_3">
      <hardwareInterface>hardware_interface/EffortJointInterface</hardwareInterface>
    </joint>
    <actuator name="Revolute_3_actr">
      <hardwareInterface>hardware_interface/EffortJointInterface</hardwareInterface>
      <mechanicalReduction>1</mechanicalReduction>
    </actuator>
  </transmission>
  <transmission name="Revolute_4_tran">
    <type>transmission_interface/SimpleTransmission</type>
    <joint name="Revolute_4">
      <hardwareInterface>hardware_interface/EffortJointInterface</hardwareInterface>
    </joint>
    <actuator name="Revolute_4_actr">
      <hardwareInterface>hardware_interface/EffortJointInterface</hardwareInterface>
      <mechanicalReduction>1</mechanicalReduction>
    </actuator>
  </transmission>
  <transmission name="Revolute_5_tran">
    <type>transmission_interface/SimpleTransmission</type>
    <joint name="Revolute_5">
      <hardwareInterface>hardware_interface/EffortJointInterface</hardwareInterface>
    </joint>
    <actuator name="Revolute_5_actr">
      <hardwareInterface>hardware_interface/EffortJointInterface</hardwareInterface>
      <mechanicalReduction>1</mechanicalReduction>
    </actuator>
  </transmission>
  <transmission name="Revolute_6_tran">
    <type>transmission_interface/SimpleTransmission</type>
    <joint name="Revolute_6">
      <hardwareInterface>hardware_interface/EffortJointInterface</hardwareInterface>
    </joint>
    <actuator name="Revolute_6_actr">
      <hardwareInterface>hardware_interface/EffortJointInterface</hardwareInterface>
      <mechanicalReduction>1</mechanicalReduction>
    </actuator>
  </transmission>
  <link name="base_link">
    <inertial>
      <origin rpy="0 0 0" xyz="0.001924209931808292 9.588003529118677e-06 -0.017397201457223316"/>
      <mass value="10.00"/>
      <inertia ixx="0.013016" ixy="2e-06" ixz="-5.1e-05" iyy="0.013601" iyz="-1e-06" izz="0.02409"/>
    </inertial>
    <visual>
      <origin rpy="0 0 0" xyz="0 0 0"/>
      <geometry>
        <mesh filename="../meshes/base_link.stl" scale="0.001 0.001 0.001"/>
      </geometry>
      <material name="aluminum_satin"/>
    </visual>
    <collision>
      <origin rpy="0 0 0" xyz="0 0 0"/>
      <geometry>
        <mesh filename="../meshes/base_link.stl" scale="0.001 0.001 0.001"/>
      </geometry>
    </collision>
  </link>
  <link name="arm_bracket_temp_v12_1">
    <inertial>
      <origin rpy="0 0 0" xyz="0.007959481790445908 0.009999999999998583 0.02273935784904592"/>
      <mass value="0.16496925038992882"/>
      <inertia ixx="9.9e-05" ixy="-0.0" ixz="-1e-05" iyy="6.1e-05" iyz="-0.0" izz="5.2e-05"/>
    </inertial>
    <visual>
      <origin rpy="0 0 0" xyz="-0.047 0.01 -0.005"/>
      <geometry>
        <mesh filename="../meshes/arm_bracket_temp_v12_1.stl" scale="0.001 0.001 0.001"/>
      </geometry>
      <material name="steel_satin"/>
    </visual>
    <collision>
      <origin rpy="0 0 0" xyz="-0.047 0.01 -0.005"/>
      <geometry>
        <mesh filename="../meshes/arm_bracket_temp_v12_1.stl" scale="0.001 0.001 0.001"/>
      </geometry>
    </collision>
  </link>
  <link name="raspi4_bracket_v1_1">
    <inertial>
      <origin rpy="0 0 0" xyz="0.0020951925076898026 -0.0036289475514907216 0.011212626337856312"/>
      <mass value="0.10292684148685698"/>
      <inertia ixx="2.6e-05" ixy="-9e-06" ixz="-2e-06" iyy="3.6e-05" iyz="4e-06" izz="4.4e-05"/>
    </inertial>
    <visual>
      <origin rpy="0 0 0" xyz="0.04 -0.069282 -0.005"/>
      <geometry>
        <mesh filename="../meshes/raspi4_bracket_v1_1.stl" scale="0.001 0.001 0.001"/>
      </geometry>
      <material name="steel_satin"/>
    </visual>
    <collision>
      <origin rpy="0 0 0" xyz="0.04 -0.069282 -0.005"/>
      <geometry>
        <mesh filename="../meshes/raspi4_bracket_v1_1.stl" scale="0.001 0.001 0.001"/>
      </geometry>
    </collision>
  </link>
  <link name="raspi4_v2_1">
    <inertial>
      <origin rpy="0 0 0" xyz="-0.00749999999999993 0.01299008311032395 0.038590101642230826"/>
      <mass value="0.7390104624417327"/>
      <inertia ixx="0.000507" ixy="-7.2e-05" ixz="1e-06" iyy="0.00059" iyz="1e-06" izz="0.000215"/>
    </inertial>
    <visual>
      <origin rpy="0 0 0" xyz="0.0335 -0.058024 -0.026"/>
      <geometry>
        <mesh filename="../meshes/raspi4_v2_1.stl" scale="0.001 0.001 0.001"/>
      </geometry>
      <material name="steel_satin"/>
    </visual>
    <collision>
      <origin rpy="0 0 0" xyz="0.0335 -0.058024 -0.026"/>
      <geometry>
        <mesh filename="../meshes/raspi4_v2_1.stl" scale="0.001 0.001 0.001"/>
      </geometry>
    </collision>
  </link>
  <link name="lipo_bracket_v5_1">
    <inertial>
      <origin rpy="0 0 0" xyz="-0.007072287607066324 -0.03064999999999981 0.02557238675910756"/>
      <mass value="0.15095338739595293"/>
      <inertia ixx="0.000136" ixy="-0.0" ixz="1e-06" iyy="0.000109" iyz="0.0" izz="9.8e-05"/>
    </inertial>
    <visual>
      <origin rpy="0 0 0" xyz="0.064425 -0.03065 -0.005"/>
      <geometry>
        <mesh filename="../meshes/lipo_bracket_v5_1.stl" scale="0.001 0.001 0.001"/>
      </geometry>
      <material name="steel_satin"/>
    </visual>
    <collision>
      <origin rpy="0 0 0" xyz="0.064425 -0.03065 -0.005"/>
      <geometry>
        <mesh filename="../meshes/lipo_bracket_v5_1.stl" scale="0.001 0.001 0.001"/>
      </geometry>
    </collision>
  </link>
  <link name="DZ47B_63_circuit_breaker_holder_v3_1">
    <inertial>
      <origin rpy="0 0 0" xyz="0.03862239340692045 -0.022298666174134715 0.0029380076866297187"/>
      <mass value="0.012274791356152887"/>
      <inertia ixx="5e-06" ixy="8e-06" ixz="-0.0" iyy="1.5e-05" iyz="0.0" izz="2e-05"/>
    </inertial>
    <visual>
      <origin rpy="0 0 0" xyz="0.076172 0.044934 -0.005"/>
      <geometry>
        <mesh filename="../meshes/DZ47B_63_circuit_breaker_holder_v3_1.stl" scale="0.001 0.001 0.001"/>
      </geometry>
      <material name="steel_satin"/>
    </visual>
    <collision>
      <origin rpy="0 0 0" xyz="0.076172 0.044934 -0.005"/>
      <geometry>
        <mesh filename="../meshes/DZ47B_63_circuit_breaker_holder_v3_1.stl" scale="0.001 0.001 0.001"/>
      </geometry>
    </collision>
  </link>
  <link name="arm_root_v4_1">
    <inertial>
      <origin rpy="0 0 0" xyz="0.02559296991432554 1.2574053551176077e-11 -0.009138901606431792"/>
      <mass value="0.06457976620923557"/>
      <inertia ixx="1.3e-05" ixy="0.0" ixz="-1e-06" iyy="2.4e-05" iyz="0.0" izz="1.9e-05"/>
    </inertial>
    <visual>
      <origin rpy="0 0 0" xyz="-0.0615 -0.0 -0.045"/>
      <geometry>
        <mesh filename="../meshes/arm_root_v4_1.stl" scale="0.001 0.001 0.001"/>
      </geometry>
      <material name="abs_white"/>
    </visual>
    <collision>
      <origin rpy="0 0 0" xyz="-0.0615 -0.0 -0.045"/>
      <geometry>
        <mesh filename="../meshes/arm_root_v4_1.stl" scale="0.001 0.001 0.001"/>
      </geometry>
    </collision>
  </link>
  <link name="pitch_1_test_v3_1">
    <inertial>
      <origin rpy="0 0 0" xyz="0.04097968346475826 0.0006820959366182021 -0.0001307207329616436"/>
      <mass value="0.08186133563123103"/>
      <inertia ixx="2.7e-05" ixy="-1e-06" ixz="-1e-05" iyy="4.3e-05" iyz="-0.0" izz="3.7e-05"/>
    </inertial>
    <visual>
      <origin rpy="0 0 0" xyz="-0.1027 0.0 -0.05805"/>
      <geometry>
        <mesh filename="../meshes/pitch_1_test_v3_1.stl" scale="0.001 0.001 0.001"/>
      </geometry>
      <material name="abs_white"/>
    </visual>
    <collision>
      <origin rpy="0 0 0" xyz="-0.1027 0.0 -0.05805"/>
      <geometry>
        <mesh filename="../meshes/pitch_1_test_v3_1.stl" scale="0.001 0.001 0.001"/>
      </geometry>
    </collision>
  </link>
  <link name="roll_1_test_v3_1">
    <inertial>
      <origin rpy="0 0 0" xyz="0.0363742814442784 0.0212000000095127 0.015160914691842164"/>
      <mass value="0.07353297901744495"/>
      <inertia ixx="2.4e-05" ixy="0.0" ixz="-1e-06" iyy="2.9e-05" iyz="-0.0" izz="2.1e-05"/>
    </inertial>
    <visual>
      <origin rpy="0 0 0" xyz="-0.1649 0.02035 -0.0635"/>
      <geometry>
        <mesh filename="../meshes/roll_1_test_v3_1.stl" scale="0.001 0.001 0.001"/>
      </geometry>
      <material name="abs_white"/>
    </visual>
    <collision>
      <origin rpy="0 0 0" xyz="-0.1649 0.02035 -0.0635"/>
      <geometry>
        <mesh filename="../meshes/roll_1_test_v3_1.stl" scale="0.001 0.001 0.001"/>
      </geometry>
    </collision>
  </link>
  <link name="pitch_2_test_v3_1">
    <inertial>
      <origin rpy="0 0 0" xyz="0.029877529047602214 0.0001958957866964999 -2.9469195139686377e-10"/>
      <mass value="0.06668343069893205"/>
      <inertia ixx="1.4e-05" ixy="-1e-06" ixz="-0.0" iyy="2e-05" iyz="-0.0" izz="2.6e-05"/>
    </inertial>
    <visual>
      <origin rpy="0 0 0" xyz="-0.2213 -0.00085 -0.0635"/>
      <geometry>
        <mesh filename="../meshes/pitch_2_test_v3_1.stl" scale="0.001 0.001 0.001"/>
      </geometry>
      <material name="abs_white"/>
    </visual>
    <collision>
      <origin rpy="0 0 0" xyz="-0.2213 -0.00085 -0.0635"/>
      <geometry>
        <mesh filename="../meshes/pitch_2_test_v3_1.stl" scale="0.001 0.001 0.001"/>
      </geometry>
    </collision>
  </link>
  <link name="roll_2_test_v3_1">
    <inertial>
      <origin rpy="0 0 0" xyz="0.036375491747628774 0.021200000009496393 0.015187663571532395"/>
      <mass value="0.07365581710871624"/>
      <inertia ixx="2.4e-05" ixy="0.0" ixz="-1e-06" iyy="2.9e-05" iyz="-0.0" izz="2.1e-05"/>
    </inertial>
    <visual>
      <origin rpy="0 0 0" xyz="-0.2675 0.02015 -0.0635"/>
      <geometry>
        <mesh filename="../meshes/roll_2_test_v3_1.stl" scale="0.001 0.001 0.001"/>
      </geometry>
      <material name="abs_white"/>
    </visual>
    <collision>
      <origin rpy="0 0 0" xyz="-0.2675 0.02015 -0.0635"/>
      <geometry>
        <mesh filename="../meshes/roll_2_test_v3_1.stl" scale="0.001 0.001 0.001"/>
      </geometry>
    </collision>
  </link>
  <link name="hand_unit_v3_1">
    <inertial>
      <origin rpy="0 0 0" xyz="0.031683675390487276 -0.00023986066792197516 -0.011102966860764112"/>
      <mass value="0.0952280970557457"/>
      <inertia ixx="4.8e-05" ixy="-0.0" ixz="1.9e-05" iyy="7.4e-05" iyz="1e-06" izz="5.4e-05"/>
    </inertial>
    <visual>
      <origin rpy="0 0 0" xyz="-0.3239 -0.00105 -0.0635"/>
      <geometry>
        <mesh filename="../meshes/hand_unit_v3_1.stl" scale="0.001 0.001 0.001"/>
      </geometry>
      <material name="abs_white"/>
    </visual>
    <collision>
      <origin rpy="0 0 0" xyz="-0.3239 -0.00105 -0.0635"/>
      <geometry>
        <mesh filename="../meshes/hand_unit_v3_1.stl" scale="0.001 0.001 0.001"/>
      </geometry>
    </collision>
  </link>
  <link name="hand_finger_v7_1">
    <inertial>
      <origin rpy="0 0 0" xyz="0.03630500457367125 0.02170000000000132 0.024617294394885247"/>
      <mass value="0.024732672038933038"/>
      <inertia ixx="7e-06" ixy="-0.0" ixz="-4e-06" iyy="1.5e-05" iyz="0.0" izz="1.8e-05"/>
    </inertial>
    <visual>
      <origin rpy="0 0 0" xyz="-0.34955 0.02115 -0.0765"/>
      <geometry>
        <mesh filename="../meshes/hand_finger_v7_1.stl" scale="0.001 0.001 0.001"/>
      </geometry>
      <material name="abs_white"/>
    </visual>
    <collision>
      <origin rpy="0 0 0" xyz="-0.34955 0.02115 -0.0765"/>
      <geometry>
        <mesh filename="../meshes/hand_finger_v7_1.stl" scale="0.001 0.001 0.001"/>
      </geometry>
    </collision>
  </link>
  <joint name="Rigid 4" type="fixed">
    <origin rpy="0 0 0" xyz="0.047 -0.01 0.005"/>
    <parent link="base_link"/>
    <child link="arm_bracket_temp_v12_1"/>
  </joint>
  <joint name="Rigid 7" type="fixed">
    <origin rpy="0 0 0" xyz="-0.04 0.069282 0.005"/>
    <parent link="base_link"/>
    <child link="raspi4_bracket_v1_1"/>
  </joint>
  <joint name="Rigid 8" type="fixed">
    <origin rpy="0 0 0" xyz="0.0065 -0.011258 0.021"/>
    <parent link="raspi4_bracket_v1_1"/>
    <child link="raspi4_v2_1"/>
  </joint>
  <joint name="Rigid 16" type="fixed">
    <origin rpy="0 0 0" xyz="-0.064425 0.03065 0.005"/>
    <parent link="base_link"/>
    <child link="lipo_bracket_v5_1"/>
  </joint>
  <joint name="Rigid 17" type="fixed">
    <origin rpy="0 0 0" xyz="-0.076172 -0.044934 0.005"/>
    <parent link="base_link"/>
    <child link="DZ47B_63_circuit_breaker_holder_v3_1"/>
  </joint>
  <joint name="Rigid 26" type="fixed">
    <origin rpy="0 0 0" xyz="0.0145 0.01 0.04"/>
    <parent link="arm_bracket_temp_v12_1"/>
    <child link="arm_root_v4_1"/>
  </joint>
  <joint name="Revolute_1" type="revolute">
    <origin rpy="0 0 0" xyz="0.0412 -0.0 0.01305"/>
    <parent link="arm_root_v4_1"/>
    <child link="pitch_1_test_v3_1"/>
    <axis xyz="0.0 -0.0 -1.0"/>
    <limit effort="100" lower="-1.570796" upper="1.570796" velocity="100"/>
  </joint>
  <joint name="Revolute_2" type="revolute">
    <origin rpy="0 0 0" xyz="0.0622 -0.02035 0.00545"/>
    <parent link="pitch_1_test_v3_1"/>
    <child link="roll_1_test_v3_1"/>
    <axis xyz="-0.0 1.0 -0.0"/>
    <limit effort="100" lower="-1.396263" upper="1.919862" velocity="100"/>
  </joint>
  <joint name="Revolute_3" type="continuous">
    <origin rpy="0 0 0" xyz="0.0564 0.0212 0.0"/>
    <parent link="roll_1_test_v3_1"/>
    <child link="pitch_2_test_v3_1"/>
    <axis xyz="1.0 0.0 0.0"/>
  </joint>
  <joint name="Revolute_4" type="revolute">
    <origin rpy="0 0 0" xyz="0.0462 -0.021 0.0"/>
    <parent link="pitch_2_test_v3_1"/>
    <child link="roll_2_test_v3_1"/>
    <axis xyz="-0.0 1.0 0.0"/>
    <limit effort="100" lower="-1.48353" upper="1.919862" velocity="100"/>
  </joint>
  <joint name="Revolute_5" type="continuous">
    <origin rpy="0 0 0" xyz="0.0564 0.0212 0.0"/>
    <parent link="roll_2_test_v3_1"/>
    <child link="hand_unit_v3_1"/>
    <axis xyz="-1.0 0.0 -0.0"/>
  </joint>
  <joint name="Revolute_6" type="revolute">
    <origin rpy="0 0 0" xyz="0.02565 -0.0222 0.013"/>
    <parent link="hand_unit_v3_1"/>
    <child link="hand_finger_v7_1"/>
    <axis xyz="0.0 1.0 -0.0"/>
    <limit effort="100" lower="-1.047198" upper="0.872665" velocity="100"/>
  </joint>
</robot>
